Workbook

Sheet Resumo
A1: Análise do fornecedor Bem Mulher (Loja de R$10)
A2: Atualizada a cada leva de prints. Produtos com "S" em "Vou comprar?" entram nas contas abaixo, na quantidade da coluna "Quantas caixas/unidades comprar" (aba Produtos).
A4: Indicador | B4: Valor
A5: Produtos analisados | B5: =COUNTA(Produtos!A2:A110) -> 109
A6: Produtos marcados para comprar | B6: =COUNTIF(Produtos!T2:T110,"S") -> 36
A7: Investimento no fornecedor | B7: =SUM(Produtos!Y2:Y110) -> 3869.06
A8: Unidades compradas | B8: =SUMPRODUCT((Produtos!T2:T110="S")*Produtos!F2:F110*Produtos!X2:X110) -> 721
A9: Faturamento se vender tudo no seu site | B9: =SUM(Produtos!V2:V110) -> 10767.9
A10: Lucro se vender tudo no seu site | B10: =SUM(Produtos!W2:W110) -> 5537.1499
A11: Retorno sobre o investimento | B11: =IFERROR(B10/B7,"") -> 1.4311357
A12: Meta de lucro por mês | B12: =Premissas!$B$12 -> 1000
A15: Como usar
A16: • Texto azul com fundo amarelo = você pode alterar (preço de venda, "Vou comprar?", premissas, preço dos kits).
A17: • Preço internet "Estimado" (em dourado) = produto exato não achado; confira no Mercado Livre antes de definir o preço.
A18: • Lucro em vermelho = você perde dinheiro nesse canal com esse preço. No Mercado Livre e na Shopee, prefira vender em kit.
A19: • Use o filtro do cabeçalho na aba Produtos para ordenar por lucro, categoria ou lote.
A20: • Taxas do Mercado Livre e da Shopee são aproximadas: confira as atuais e ajuste na aba Premissas.

Sheet Premissas
A1: Premissas usadas nas contas
A2: Células em amarelo com texto azul podem ser alteradas. O resto da planilha se atualiza sozinho.
A4: Premissa | B4: Valor | C4: Observação
A5: Desconto Pix no seu site | B5: 0.05 | C5: Configuração atual da loja Élan Beauté
A6: Taxa do meio de pagamento (seu site) | B6: 0.01 | C6: Estimativa para Pix; cartão costuma ser 3–5%
A7: Embalagem por pedido/unidade (R$) | B7: 1 | C7: Estimativa: saquinho + etiqueta
A8: Mercado Livre: comissão | B8: 0.12 | C8: Aproximado (anúncio clássico, beleza). Confira a taxa atual
A9: Mercado Livre: taxa fixa por venda abaixo de R$ 79 (R$) | B9: 6.25 | C9: Aproximado. Confira a taxa atual
A10: Shopee: comissão + frete grátis | B10: 0.2 | C10: Aproximado. Confira a taxa atual
A11: Shopee: taxa fixa por item (R$) | B11: 4 | C11: Aproximado. Confira a taxa atual
A12: Meta de lucro por mês (R$) | B12: 1000 | C12: Valor de exemplo: coloque a sua meta

Sheet Produtos
A1: ID | B1: Produto | C1: Marca | D1: Categoria | E1: Lote (print) | F1: Qtd na caixa | G1: Preço no fornecedor | H1: Custo por unidade | I1: Internet: menor preço | J1: Internet: maior preço | K1: Preço internet é | L1: Seu preço de venda | M1: Lucro/un. seu site | N1: Margem seu site | O1: Lucro/un. Mercado Livre | P1: Lucro/un. Shopee | Q1: Lucro da caixa (seu site) | R1: Unidades/mês p/ meta | S1: Recomendação | T1: Vou comprar? (S/N) | U1: Observação | V1: Faturamento (se comprar) | W1: Lucro (se comprar) | X1: Quantas caixas/unidades comprar | Y1: Investimento (se comprar)
A2: P01 | B2: Pó Compacto Choco Fun | C2: Fenzza | D2: Maquiagem – Rosto | E2: 1 | F2: 24 | G2: 156.5 | H2: =IF(ISNUMBER(G2),IFERROR(G2/F2,""),"") -> 6.5208333 | I2: 14.99 | J2: 14.99 | K2: Estimado | L2: 14.9 | M2: =IFERROR(L2*(1-Premissas!$B$5)*(1-Premissas!$B$6)-H2-Premissas!$B$7,"") -> 6.4926167 | N2: =IFERROR(M2/L2,"") -> 0.43574609 | O2: =IFERROR(L2*(1-Premissas!$B$8)-Premissas!$B$9-H2-Premissas!$B$7,"") -> -0.65883333 | P2: =IFERROR(L2*(1-Premissas!$B$10)-Premissas!$B$11-H2-Premissas!$B$7,"") -> 0.39916667 | Q2: =IFERROR(M2*F2,"") -> 155.8228 | R2: =IFERROR(IF(M2>0,ROUNDUP(Premissas!$B$12/M2,0),"sem lucro"),"") -> 155 | S2: Comprar | T2: S | U2: Referência: Pó Solto Choco Fun R$ 14,99 | V2: =IF(AND(T2="S",ISNUMBER(L2),ISNUMBER(F2)),L2*F2*X2,0) -> 357.6 | W2: =IF(AND(T2="S",ISNUMBER(Q2)),Q2*X2,0) -> 155.8228 | X2: 1 | Y2: =IF(AND(T2="S",ISNUMBER(G2)),G2*X2,0) -> 156.5
A3: P02 | B3: Blush Matte Velvet Cheeks | C3: Dapop | D3: Maquiagem – Rosto | E3: 1 | F3: 24 | G3: 161.7 | H3: =IF(ISNUMBER(G3),IFERROR(G3/F3,""),"") -> 6.7375 | I3: 12 | J3: 15.9 | K3: Estimado | L3: 14.9 | M3: =IFERROR(L3*(1-Premissas!$B$5)*(1-Premissas!$B$6)-H3-Premissas!$B$7,"") -> 6.27595 | N3: =IFERROR(M3/L3,"") -> 0.4212047 | O3: =IFERROR(L3*(1-Premissas!$B$8)-Premissas!$B$9-H3-Premissas!$B$7,"") -> -0.8755 | P3: =IFERROR(L3*(1-Premissas!$B$10)-Premissas!$B$11-H3-Premissas!$B$7,"") -> 0.1825 | Q3: =IFERROR(M3*F3,"") -> 150.6228 | R3: =IFERROR(IF(M3>0,ROUNDUP(Premissas!$B$12/M3,0),"sem lucro"),"") -> 160 | S3: Comprar (kit Pele Perfeita) | T3: S | U3: Linha nova; referência: outros blushes Dapop | V3: =IF(AND(T3="S",ISNUMBER(L3),ISNUMBER(F3)),L3*F3*X3,0) -> 357.6 | W3: =IF(AND(T3="S",ISNUMBER(Q3)),Q3*X3,0) -> 150.6228 | X3: 1 | Y3: =IF(AND(T3="S",ISNUMBER(G3)),G3*X3,0) -> 161.7
A4: P03 | B4: Blush Glow Velvet Cheeks | C4: Dapop | D4: Maquiagem – Rosto | E4: 1 | F4: 24 | H4: =IF(ISNUMBER(G4),IFERROR(G4/F4,""),"") | I4: 12 | J4: 15.9 | K4: Estimado | L4: 14.9 | M4: =IFERROR(L4*(1-Premissas!$B$5)*(1-Premissas!$B$6)-H4-Premissas!$B$7,"") | N4: =IFERROR(M4/L4,"") | O4: =IFERROR(L4*(1-Premissas!$B$8)-Premissas!$B$9-H4-Premissas!$B$7,"") | P4: =IFERROR(L4*(1-Premissas!$B$10)-Premissas!$B$11-H4-Premissas!$B$7,"") | Q4: =IFERROR(M4*F4,"") | R4: =IFERROR(IF(M4>0,ROUNDUP(Premissas!$B$12/M4,0),"sem lucro"),"") | S4: Confirmar preço | T4: N | U4: Preço não apareceu no print | V4: =IF(AND(T4="S",ISNUMBER(L4),ISNUMBER(F4)),L4*F4*X4,0) -> 0 | W4: =IF(AND(T4="S",ISNUMBER(Q4)),Q4*X4,0) -> 0 | X4: 1 | Y4: =IF(AND(T4="S",ISNUMBER(G4)),G4*X4,0) -> 0
A5: P04 | B5: Pó Translúcido Solto Soft Focus | C5: Dapop | D5: Maquiagem – Rosto | E5: 1 | F5: 24 | H5: =IF(ISNUMBER(G5),IFERROR(G5/F5,""),"") | K5: Estimado | M5: =IFERROR(L5*(1-Premissas!$B$5)*(1-Premissas!$B$6)-H5-Premissas!$B$7,"") | N5: =IFERROR(M5/L5,"") | O5: =IFERROR(L5*(1-Premissas!$B$8)-Premissas!$B$9-H5-Premissas!$B$7,"") | P5: =IFERROR(L5*(1-Premissas!$B$10)-Premissas!$B$11-H5-Premissas!$B$7,"") | Q5: =IFERROR(M5*F5,"") | R5: =IFERROR(IF(M5>0,ROUNDUP(Premissas!$B$12/M5,0),"sem lucro"),"") | S5: Confirmar preço | T5: N | U5: Preço não apareceu no print | V5: =IF(AND(T5="S",ISNUMBER(L5),ISNUMBER(F5)),L5*F5*X5,0) -> 0 | W5: =IF(AND(T5="S",ISNUMBER(Q5)),Q5*X5,0) -> 0 | X5: 1 | Y5: =IF(AND(T5="S",ISNUMBER(G5)),G5*X5,0) -> 0
A6: P05 | B6: Bronzer Velvet (DP2470) | C6: Dapop | D6: Maquiagem – Rosto | E6: 1 | F6: 24 | G6: 161.7 | H6: =IF(ISNUMBER(G6),IFERROR(G6/F6,""),"") -> 6.7375 | I6: 12 | J6: 15.9 | K6: Estimado | L6: 14.9 | M6: =IFERROR(L6*(1-Premissas!$B$5)*(1-Premissas!$B$6)-H6-Premissas!$B$7,"") -> 6.27595 | N6: =IFERROR(M6/L6,"") -> 0.4212047 | O6: =IFERROR(L6*(1-Premissas!$B$8)-Premissas!$B$9-H6-Premissas!$B$7,"") -> -0.8755 | P6: =IFERROR(L6*(1-Premissas!$B$10)-Premissas!$B$11-H6-Premissas!$B$7,"") -> 0.1825 | Q6: =IFERROR(M6*F6,"") -> 150.6228 | R6: =IFERROR(IF(M6>0,ROUNDUP(Premissas!$B$12/M6,0),"sem lucro"),"") -> 160 | S6: Opcional | T6: N | V6: =IF(AND(T6="S",ISNUMBER(L6),ISNUMBER(F6)),L6*F6*X6,0) -> 0 | W6: =IF(AND(T6="S",ISNUMBER(Q6)),Q6*X6,0) -> 0 | X6: 1 | Y6: =IF(AND(T6="S",ISNUMBER(G6)),G6*X6,0) -> 0
A7: P06 | B7: Contorno Velvet (DP2471) | C7: Dapop | D7: Maquiagem – Rosto | E7: 1 | F7: 24 | G7: 161.7 | H7: =IF(ISNUMBER(G7),IFERROR(G7/F7,""),"") -> 6.7375 | I7: 12 | J7: 15.9 | K7: Estimado | L7: 14.9 | M7: =IFERROR(L7*(1-Premissas!$B$5)*(1-Premissas!$B$6)-H7-Premissas!$B$7,"") -> 6.27595 | N7: =IFERROR(M7/L7,"") -> 0.4212047 | O7: =IFERROR(L7*(1-Premissas!$B$8)-Premissas!$B$9-H7-Premissas!$B$7,"") -> -0.8755 | P7: =IFERROR(L7*(1-Premissas!$B$10)-Premissas!$B$11-H7-Premissas!$B$7,"") -> 0.1825 | Q7: =IFERROR(M7*F7,"") -> 150.6228 | R7: =IFERROR(IF(M7>0,ROUNDUP(Premissas!$B$12/M7,0),"sem lucro"),"") -> 160 | S7: Comprar (kit Pele Perfeita) | T7: S | V7: =IF(AND(T7="S",ISNUMBER(L7),ISNUMBER(F7)),L7*F7*X7,0) -> 357.6 | W7: =IF(AND(T7="S",ISNUMBER(Q7)),Q7*X7,0) -> 150.6228 | X7: 1 | Y7: =IF(AND(T7="S",ISNUMBER(G7)),G7*X7,0) -> 161.7
A8: P07 | B8: Iluminador Velvet Glow | C8: Dapop | D8: Maquiagem – Rosto | E8: 1 | F8: 24 | G8: 163.7 | H8: =IF(ISNUMBER(G8),IFERROR(G8/F8,""),"") -> 6.8208333 | I8: 15.9 | J8: 15.9 | K8: Estimado | L8: 14.9 | M8: =IFERROR(L8*(1-Premissas!$B$5)*(1-Premissas!$B$6)-H8-Premissas!$B$7,"") -> 6.1926167 | N8: =IFERROR(M8/L8,"") -> 0.41561186 | O8: =IFERROR(L8*(1-Premissas!$B$8)-Premissas!$B$9-H8-Premissas!$B$7,"") -> -0.95883333 | P8: =IFERROR(L8*(1-Premissas!$B$10)-Premissas!$B$11-H8-Premissas!$B$7,"") -> 0.099166667 | Q8: =IFERROR(M8*F8,"") -> 148.6228 | R8: =IFERROR(IF(M8>0,ROUNDUP(Premissas!$B$12/M8,0),"sem lucro"),"") -> 162 | S8: Comprar (kit Pele Perfeita) | T8: S | V8: =IF(AND(T8="S",ISNUMBER(L8),ISNUMBER(F8)),L8*F8*X8,0) -> 357.6 | W8: =IF(AND(T8="S",ISNUMBER(Q8)),Q8*X8,0) -> 148.6228 | X8: 1 | Y8: =IF(AND(T8="S",ISNUMBER(G8)),G8*X8,0) -> 163.7
A9: P08 | B9: Pó Facial Matificante Skin Filter | C9: Dapop | D9: Maquiagem – Rosto | E9: 1 | F9: 1 | G9: 5.7 | H9: =IF(ISNUMBER(G9),IFERROR(G9/F9,""),"") -> 5.7 | I9: 7.9 | J9: 10 | K9: Estimado | L9: 11.9 | M9: =IFERROR(L9*(1-Premissas!$B$5)*(1-Premissas!$B$6)-H9-Premissas!$B$7,"") -> 4.49195 | N9: =IFERROR(M9/L9,"") -> 0.37747479 | O9: =IFERROR(L9*(1-Premissas!$B$8)-Premissas!$B$9-H9-Premissas!$B$7,"") -> -2.478 | P9: =IFERROR(L9*(1-Premissas!$B$10)-Premissas!$B$11-H9-Premissas!$B$7,"") -> -1.18 | Q9: =IFERROR(M9*F9,"") -> 4.49195 | R9: =IFERROR(IF(M9>0,ROUNDUP(Premissas!$B$12/M9,0),"sem lucro"),"") -> 223 | S9: Confirmar preço | T9: N | U9: Site diz "C/24 Unid" por R$ 5,70: confirmar se é caixa ou unidade | V9: =IF(AND(T9="S",ISNUMBER(L9),ISNUMBER(F9)),L9*F9*X9,0) -> 0 | W9: =IF(AND(T9="S",ISNUMBER(Q9)),Q9*X9,0) -> 0 | X9: 12 | Y9: =IF(AND(T9="S",ISNUMBER(G9)),G9*X9,0) -> 0
A10: P09 | B10: Água Micelar Pantenol e Ác. Hialurônico 200ml | C10: Dapop | D10: Skincare | E10: 1 | F10: 1 | G10: 5.7 | H10: =IF(ISNUMBER(G10),IFERROR(G10/F10,""),"") -> 5.7 | I10: 9.99 | J10: 12 | K10: Confirmado | L10: 12.9 | M10: =IFERROR(L10*(1-Premissas!$B$5)*(1-Premissas!$B$6)-H10-Premissas!$B$7,"") -> 5.43245 | N10: =IFERROR(M10/L10,"") -> 0.42112016 | O10: =IFERROR(L10*(1-Premissas!$B$8)-Premissas!$B$9-H10-Premissas!$B$7,"") -> -1.598 | P10: =IFERROR(L10*(1-Premissas!$B$10)-Premissas!$B$11-H10-Premissas!$B$7,"") -> -0.38 | Q10: =IFERROR(M10*F10,"") -> 5.43245 | R10: =IFERROR(IF(M10>0,ROUNDUP(Premissas!$B$12/M10,0),"sem lucro"),"") -> 185 | S10: Comprar | T10: S | V10: =IF(AND(T10="S",ISNUMBER(L10),ISNUMBER(F10)),L10*F10*X10,0) -> 154.8 | W10: =IF(AND(T10="S",ISNUMBER(Q10)),Q10*X10,0) -> 65.1894 | X10: 12 | Y10: =IF(AND(T10="S",ISNUMBER(G10)),G10*X10,0) -> 68.4
A11: P10 | B11: Tônico Facial Ácido Glicólico 200ml | C11: Dapop | D11: Skincare | E11: 1 | F11: 1 | G11: 5.7 | H11: =IF(ISNUMBER(G11),IFERROR(G11/F11,""),"") -> 5.7 | I11: 12.9 | J11: 16.99 | K11: Confirmado | L11: 14.9 | M11: =IFERROR(L11*(1-Premissas!$B$5)*(1-Premissas!$B$6)-H11-Premissas!$B$7,"") -> 7.31345 | N11: =IFERROR(M11/L11,"") -> 0.49083557 | O11: =IFERROR(L11*(1-Premissas!$B$8)-Premissas!$B$9-H11-Premissas!$B$7,"") -> 0.162 | P11: =IFERROR(L11*(1-Premissas!$B$10)-Premissas!$B$11-H11-Premissas!$B$7,"") -> 1.22 | Q11: =IFERROR(M11*F11,"") -> 7.31345 | R11: =IFERROR(IF(M11>0,ROUNDUP(Premissas!$B$12/M11,0),"sem lucro"),"") -> 137 | S11: Comprar | T11: S | V11: =IF(AND(T11="S",ISNUMBER(L11),ISNUMBER(F11)),L11*F11*X11,0) -> 178.8 | W11: =IF(AND(T11="S",ISNUMBER(Q11)),Q11*X11,0) -> 87.7614 | X11: 12 | Y11: =IF(AND(T11="S",ISNUMBER(G11)),G11*X11,0) -> 68.4
A12: P11 | B12: Demaquilante Aloe Vera e Alantoína 200ml | C12: Dapop | D12: Skincare | E12: 1 | F12: 1 | G12: 5.7 | H12: =IF(ISNUMBER(G12),IFERROR(G12/F12,""),"") -> 5.7 | I12: 9.99 | J12: 12 | K12: Estimado | L12: 12.9 | M12: =IFERROR(L12*(1-Premissas!$B$5)*(1-Premissas!$B$6)-H12-Premissas!$B$7,"") -> 5.43245 | N12: =IFERROR(M12/L12,"") -> 0.42112016 | O12: =IFERROR(L12*(1-Premissas!$B$8)-Premissas!$B$9-H12-Premissas!$B$7,"") -> -1.598 | P12: =IFERROR(L12*(1-Premissas!$B$10)-Premissas!$B$11-H12-Premissas!$B$7,"") -> -0.38 | Q12: =IFERROR(M12*F12,"") -> 5.43245 | R12: =IFERROR(IF(M12>0,ROUNDUP(Premissas!$B$12/M12,0),"sem lucro"),"") -> 185 | S12: Opcional | T12: N | V12: =IF(AND(T12="S",ISNUMBER(L12),ISNUMBER(F12)),L12*F12*X12,0) -> 0 | W12: =IF(AND(T12="S",ISNUMBER(Q12)),Q12*X12,0) -> 0 | X12: 12 | Y12: =IF(AND(T12="S",ISNUMBER(G12)),G12*X12,0) -> 0
A13: P12 | B13: Loção Adstringente Chá Verde 200ml | C13: Dapop | D13: Skincare | E13: 1 | F13: 1 | G13: 5.7 | H13: =IF(ISNUMBER(G13),IFERROR(G13/F13,""),"") -> 5.7 | I13: 9.99 | J13: 12 | K13: Estimado | L13: 12.9 | M13: =IFERROR(L13*(1-Premissas!$B$5)*(1-Premissas!$B$6)-H13-Premissas!$B$7,"") -> 5.43245 | N13: =IFERROR(M13/L13,"") -> 0.42112016 | O13: =IFERROR(L13*(1-Premissas!$B$8)-Premissas!$B$9-H13-Premissas!$B$7,"") -> -1.598 | P13: =IFERROR(L13*(1-Premissas!$B$10)-Premissas!$B$11-H13-Premissas!$B$7,"") -> -0.38 | Q13: =IFERROR(M13*F13,"") -> 5.43245 | R13: =IFERROR(IF(M13>0,ROUNDUP(Premissas!$B$12/M13,0),"sem lucro"),"") -> 185 | S13: Comprar (kit Rotina Skincare) | T13: S | V13: =IF(AND(T13="S",ISNUMBER(L13),ISNUMBER(F13)),L13*F13*X13,0) -> 154.8 | W13: =IF(AND(T13="S",ISNUMBER(Q13)),Q13*X13,0) -> 65.1894 | X13: 12 | Y13: =IF(AND(T13="S",ISNUMBER(G13)),G13*X13,0) -> 68.4
A14: P13 | B14: Água Micelar Vitamina C e Ác. Hialurônico 200ml | C14: Dapop | D14: Skincare | E14: 1 | F14: 1 | G14: 5.7 | H14: =IF(ISNUMBER(G14),IFERROR(G14/F14,""),"") -> 5.7 | I14: 9.99 | J14: 12 | K14: Confirmado | L14: 12.9 | M14: =IFERROR(L14*(1-Premissas!$B$5)*(1-Premissas!$B$6)-H14-Premissas!$B$7,"") -> 5.43245 | N14: =IFERROR(M14/L14,"") -> 0.42112016 | O14: =IFERROR(L14*(1-Premissas!$B$8)-Premissas!$B$9-H14-Premissas!$B$7,"") -> -1.598 | P14: =IFERROR(L14*(1-Premissas!$B$10)-Premissas!$B$11-H14-Premissas!$B$7,"") -> -0.38 | Q14: =IFERROR(M14*F14,"") -> 5.43245 | R14: =IFERROR(IF(M14>0,ROUNDUP(Premissas!$B$12/M14,0),"sem lucro"),"") -> 185 | S14: Opcional | T14: N | V14: =IF(AND(T14="S",ISNUMBER(L14),ISNUMBER(F14)),L14*F14*X14,0) -> 0 | W14: =IF(AND(T14="S",ISNUMBER(Q14)),Q14*X14,0) -> 0 | X14: 12 | Y14: =IF(AND(T14="S",ISNUMBER(G14)),G14*X14,0) -> 0
A15: P14 | B15: Água Micelar Rosa Mosqueta e Niacinamida 200ml | C15: Dapop | D15: Skincare | E15: 1 | F15: 1 | G15: 5.7 | H15: =IF(ISNUMBER(G15),IFERROR(G15/F15,""),"") -> 5.7 | I15: 9.99 | J15: 12 | K15: Confirmado | L15: 12.9 | M15: =IFERROR(L15*(1-Premissas!$B$5)*(1-Premissas!$B$6)-H15-Premissas!$B$7,"") -> 5.43245 | N15: =IFERROR(M15/L15,"") -> 0.42112016 | O15: =IFERROR(L15*(1-Premissas!$B$8)-Premissas!$B$9-H15-Premissas!$B$7,"") -> -1.598 | P15: =IFERROR(L15*(1-Premissas!$B$10)-Premissas!$B$11-H15-Premissas!$B$7,"") -> -0.38 | Q15: =IFERROR(M15*F15,"") -> 5.43245 | R15: =IFERROR(IF(M15>0,ROUNDUP(Premissas!$B$12/M15,0),"sem lucro"),"") -> 185 | S15: Opcional | T15: N | V15: =IF(AND(T15="S",ISNUMBER(L15),ISNUMBER(F15)),L15*F15*X15,0) -> 0 | W15: =IF(AND(T15="S",ISNUMBER(Q15)),Q15*X15,0) -> 0 | X15: 12 | Y15: =IF(AND(T15="S",ISNUMBER(G15)),G15*X15,0) -> 0
A16: P15 | B16: Kit Esponjas Makeup Blender Puff c/4 | C16: Mahav | D16: Acessórios | E16: 1 | F16: 1 | G16: 5.3 | H16: =IF(ISNUMBER(G16),IFERROR(G16/F16,""),"") -> 5.3 | I16: 13.9 | J16: 19.9 | K16: Confirmado | L16: 16.9 | M16: =IFERROR(L16*(1-Premissas!$B$5)*(1-Premissas!$B$6)-H16-Premissas!$B$7,"") -> 9.59445 | N16: =IFERROR(M16/L16,"") -> 0.56771893 | O16: =IFERROR(L16*(1-Premissas!$B$8)-Premissas!$B$9-H16-Premissas!$B$7,"") -> 2.322 | P16: =IFERROR(L16*(1-Premissas!$B$10)-Premissas!$B$11-H16-Premissas!$B$7,"") -> 3.22 | Q16: =IFERROR(M16*F16,"") -> 9.59445 | R16: =IFERROR(IF(M16>0,ROUNDUP(Premissas!$B$12/M16,0),"sem lucro"),"") -> 105 | S16: Comprar | T16: S | V16: =IF(AND(T16="S",ISNUMBER(L16),ISNUMBER(F16)),L16*F16*X16,0) -> 202.8 | W16: =IF(AND(T16="S",ISNUMBER(Q16)),Q16*X16,0) -> 115.1334 | X16: 12 | Y16: =IF(AND(T16="S",ISNUMBER(G16)),G16*X16,0) -> 63.6
A17: P16 | B17: Esponja Gota Makeup Blender Choco/Cherry | C17: Mahav | D17: Acessórios | E17: 1 | F17: 1 | G17: 2.6 | H17: =IF(ISNUMBER(G17),IFERROR(G17/F17,""),"") -> 2.6 | I17: 6.9 | J17: 6.9 | K17: Estimado | L17: 7.9 | M17: =IFERROR(L17*(1-Premissas!$B$5)*(1-Premissas!$B$6)-H17-Premissas!$B$7,"") -> 3.82995 | N17: =IFERROR(M17/L17,"") -> 0.4848038 | O17: =IFERROR(L17*(1-Premissas!$B$8)-Premissas!$B$9-H17-Premissas!$B$7,"") -> -2.898 | P17: =IFERROR(L17*(1-Premissas!$B$10)-Premissas!$B$11-H17-Premissas!$B$7,"") -> -1.28 | Q17: =IFERROR(M17*F17,"") -> 3.82995 | R17: =IFERROR(IF(M17>0,ROUNDUP(Premissas!$B$12/M17,0),"sem lucro"),"") -> 262 | S17: Só em kit | T17: N | V17: =IF(AND(T17="S",ISNUMBER(L17),ISNUMBER(F17)),L17*F17*X17,0) -> 0 | W17: =IF(AND(T17="S",ISNUMBER(Q17)),Q17*X17,0) -> 0 | X17: 12 | Y17: =IF(AND(T17="S",ISNUMBER(G17)),G17*X17,0) -> 0
A18: P17 | B18: Esponja Chanfrada Makeup Blender Cut | C18: Mahav | D18: Acessórios | E18: 1 | F18: 1 | G18: 2.6 | H18: =IF(ISNUMBER(G18),IFERROR(G18/F18,""),"") -> 2.6 | I18: 6.9 | J18: 6.9 | K18: Estimado | L18: 7.9 | M18: =IFERROR(L18*(1-Premissas!$B$5)*(1-Premissas!$B$6)-H18-Premissas!$B$7,"") -> 3.82995 | N18: =IFERROR(M18/L18,"") -> 0.4848038 | O18: =IFERROR(L18*(1-Premissas!$B$8)-Premissas!$B$9-H18-Premissas!$B$7,"") -> -2.898 | P18: =IFERROR(L18*(1-Premissas!$B$10)-Premissas!$B$11-H18-Premissas!$B$7,"") -> -1.28 | Q18: =IFERROR(M18*F18,"") -> 3.82995 | R18: =IFERROR(IF(M18>0,ROUNDUP(Premissas!$B$12/M18,0),"sem lucro"),"") -> 262 | S18: Só em kit | T18: N | V18: =IF(AND(T18="S",ISNUMBER(L18),ISNUMBER(F18)),L18*F18*X18,0) -> 0 | W18: =IF(AND(T18="S",ISNUMBER(Q18)),Q18*X18,0) -> 0 | X18: 12 | Y18: =IF(AND(T18="S",ISNUMBER(G18)),G18*X18,0) -> 0
A19: P18 | B19: Lips e Cheeks Cream | C19: Miss Romantic | D19: Maquiagem – Lábios | E19: 1 | F19: 24 | G19: 101.99 | H19: =IF(ISNUMBER(G19),IFERROR(G19/F19,""),"") -> 4.2495833 | I19: 10 | J19: 10 | K19: Estimado | L19: 11.9 | M19: =IFERROR(L19*(1-Premissas!$B$5)*(1-Premissas!$B$6)-H19-Premissas!$B$7,"") -> 5.9423667 | N19: =IFERROR(M19/L19,"") -> 0.49935854 | O19: =IFERROR(L19*(1-Premissas!$B$8)-Premissas!$B$9-H19-Premissas!$B$7,"") -> -1.0275833 | P19: =IFERROR(L19*(1-Premissas!$B$10)-Premissas!$B$11-H19-Premissas!$B$7,"") -> 0.27041667 | Q19: =IFERROR(M19*F19,"") -> 142.6168 | R19: =IFERROR(IF(M19>0,ROUNDUP(Premissas!$B$12/M19,0),"sem lucro"),"") -> 169 | S19: Opcional | T19: N | V19: =IF(AND(T19="S",ISNUMBER(L19),ISNUMBER(F19)),L19*F19*X19,0) -> 0 | W19: =IF(AND(T19="S",ISNUMBER(Q19)),Q19*X19,0) -> 0 | X19: 1 | Y19: =IF(AND(T19="S",ISNUMBER(G19)),G19*X19,0) -> 0
A20: P19 | B20: Lip Gloss Sweet | C20: Miss Romantic | D20: Maquiagem – Lábios | E20: 1 | F20: 24 | G20: 90.99 | H20: =IF(ISNUMBER(G20),IFERROR(G20/F20,""),"") -> 3.79125 | I20: 10 | J20: 10 | K20: Estimado | L20: 9.9 | M20: =IFERROR(L20*(1-Premissas!$B$5)*(1-Premissas!$B$6)-H20-Premissas!$B$7,"") -> 4.5197 | N20: =IFERROR(M20/L20,"") -> 0.45653535 | O20: =IFERROR(L20*(1-Premissas!$B$8)-Premissas!$B$9-H20-Premissas!$B$7,"") -> -2.32925 | P20: =IFERROR(L20*(1-Premissas!$B$10)-Premissas!$B$11-H20-Premissas!$B$7,"") -> -0.87125 | Q20: =IFERROR(M20*F20,"") -> 108.4728 | R20: =IFERROR(IF(M20>0,ROUNDUP(Premissas!$B$12/M20,0),"sem lucro"),"") -> 222 | S20: Limitar (muitos gloss) | T20: N | V20: =IF(AND(T20="S",ISNUMBER(L20),ISNUMBER(F20)),L20*F20*X20,0) -> 0 | W20: =IF(AND(T20="S",ISNUMBER(Q20)),Q20*X20,0) -> 0 | X20: 1 | Y20: =IF(AND(T20="S",ISNUMBER(G20)),G20*X20,0) -> 0
A21: P20 | B21: Lip Liner Sweet Linha dos Lábios | C21: Miss Romantic | D21: Maquiagem – Lábios | E21: 1 | F21: 24 | G21: 64.2 | H21: =IF(ISNUMBER(G21),IFERROR(G21/F21,""),"") -> 2.675 | I21: 5 | J21: 10 | K21: Estimado | L21: 7.9 | M21: =IFERROR(L21*(1-Premissas!$B$5)*(1-Premissas!$B$6)-H21-Premissas!$B$7,"") -> 3.75495 | N21: =IFERROR(M21/L21,"") -> 0.47531013 | O21: =IFERROR(L21*(1-Premissas!$B$8)-Premissas!$B$9-H21-Premissas!$B$7,"") -> -2.973 | P21: =IFERROR(L21*(1-Premissas!$B$10)-Premissas!$B$11-H21-Premissas!$B$7,"") -> -1.355 | Q21: =IFERROR(M21*F21,"") -> 90.1188 | R21: =IFERROR(IF(M21>0,ROUNDUP(Premissas!$B$12/M21,0),"sem lucro"),"") -> 267 | S21: Só em kit | T21: N | V21: =IF(AND(T21="S",ISNUMBER(L21),ISNUMBER(F21)),L21*F21*X21,0) -> 0 | W21: =IF(AND(T21="S",ISNUMBER(Q21)),Q21*X21,0) -> 0 | X21: 1 | Y21: =IF(AND(T21="S",ISNUMBER(G21)),G21*X21,0) -> 0
A22: P21 | B22: Máscara para Cílios Natural Curling | C22: Miss Romantic | D22: Maquiagem – Olhos | E22: 2 | F22: 24 | G22: 160.4 | H22: =IF(ISNUMBER(G22),IFERROR(G22/F22,""),"") -> 6.6833333 | I22: 12.9 | J22: 12.9 | K22: Estimado | L22: 12.9 | M22: =IFERROR(L22*(1-Premissas!$B$5)*(1-Premissas!$B$6)-H22-Premissas!$B$7,"") -> 4.4491167 | N22: =IFERROR(M22/L22,"") -> 0.34489276 | O22: =IFERROR(L22*(1-Premissas!$B$8)-Premissas!$B$9-H22-Premissas!$B$7,"") -> -2.5813333 | P22: =IFERROR(L22*(1-Premissas!$B$10)-Premissas!$B$11-H22-Premissas!$B$7,"") -> -1.3633333 | Q22: =IFERROR(M22*F22,"") -> 106.7788 | R22: =IFERROR(IF(M22>0,ROUNDUP(Premissas!$B$12/M22,0),"sem lucro"),"") -> 225 | S22: Trocada pela Super Poderes 36h | T22: N | V22: =IF(AND(T22="S",ISNUMBER(L22),ISNUMBER(F22)),L22*F22*X22,0) -> 0 | W22: =IF(AND(T22="S",ISNUMBER(Q22)),Q22*X22,0) -> 0 | X22: 1 | Y22: =IF(AND(T22="S",ISNUMBER(G22)),G22*X22,0) -> 0
A23: P22 | B23: Cílios Postiços 8D (F007/F011/F012/F019/F022) | C23: Sabrina Sato | D23: Maquiagem – Olhos | E23: 2 | F23: 10 | G23: 37.8 | H23: =IF(ISNUMBER(G23),IFERROR(G23/F23,""),"") -> 3.78 | I23: 4.06 | J23: 10.99 | K23: Confirmado | L23: 9.9 | M23: =IFERROR(L23*(1-Premissas!$B$5)*(1-Premissas!$B$6)-H23-Premissas!$B$7,"") -> 4.53095 | N23: =IFERROR(M23/L23,"") -> 0.45767172 | O23: =IFERROR(L23*(1-Premissas!$B$8)-Premissas!$B$9-H23-Premissas!$B$7,"") -> -2.318 | P23: =IFERROR(L23*(1-Premissas!$B$10)-Premissas!$B$11-H23-Premissas!$B$7,"") -> -0.86 | Q23: =IFERROR(M23*F23,"") -> 45.3095 | R23: =IFERROR(IF(M23>0,ROUNDUP(Premissas!$B$12/M23,0),"sem lucro"),"") -> 221 | S23: Comprar | T23: S | U23: 5 modelos, mesmo preço. Pedir nota fiscal e confirmar que são originais | V23: =IF(AND(T23="S",ISNUMBER(L23),ISNUMBER(F23)),L23*F23*X23,0) -> 99 | W23: =IF(AND(T23="S",ISNUMBER(Q23)),Q23*X23,0) -> 45.3095 | X23: 1 | Y23: =IF(AND(T23="S",ISNUMBER(G23)),G23*X23,0) -> 37.8
A24: P23 | B24: Sérum Facial Ácido Hialurônico Reflection 30ml | C24: Safira | D24: Skincare | E24: 2 | F24: 1 | G24: 6.3 | H24: =IF(ISNUMBER(G24),IFERROR(G24/F24,""),"") -> 6.3 | I24: 15 | J24: 20 | K24: Estimado | L24: 16.9 | M24: =IFERROR(L24*(1-Premissas!$B$5)*(1-Premissas!$B$6)-H24-Premissas!$B$7,"") -> 8.59445 | N24: =IFERROR(M24/L24,"") -> 0.50854734 | O24: =IFERROR(L24*(1-Premissas!$B$8)-Premissas!$B$9-H24-Premissas!$B$7,"") -> 1.322 | P24: =IFERROR(L24*(1-Premissas!$B$10)-Premissas!$B$11-H24-Premissas!$B$7,"") -> 2.22 | Q24: =IFERROR(M24*F24,"") -> 8.59445 | R24: =IFERROR(IF(M24>0,ROUNDUP(Premissas!$B$12/M24,0),"sem lucro"),"") -> 117 | S24: Comprar (kit Pele de Vidro) | T24: S | V24: =IF(AND(T24="S",ISNUMBER(L24),ISNUMBER(F24)),L24*F24*X24,0) -> 202.8 | W24: =IF(AND(T24="S",ISNUMBER(Q24)),Q24*X24,0) -> 103.1334 | X24: 12 | Y24: =IF(AND(T24="S",ISNUMBER(G24)),G24*X24,0) -> 75.6
A25: P24 | B25: Sérum Facial Clareador Reflection 30ml | C25: Safira | D25: Skincare | E25: 2 | F25: 1 | G25: 6.3 | H25: =IF(ISNUMBER(G25),IFERROR(G25/F25,""),"") -> 6.3 | I25: 15 | J25: 20 | K25: Estimado | L25: 16.9 | M25: =IFERROR(L25*(1-Premissas!$B$5)*(1-Premissas!$B$6)-H25-Premissas!$B$7,"") -> 8.59445 | N25: =IFERROR(M25/L25,"") -> 0.50854734 | O25: =IFERROR(L25*(1-Premissas!$B$8)-Premissas!$B$9-H25-Premissas!$B$7,"") -> 1.322 | P25: =IFERROR(L25*(1-Premissas!$B$10)-Premissas!$B$11-H25-Premissas!$B$7,"") -> 2.22 | Q25: =IFERROR(M25*F25,"") -> 8.59445 | R25: =IFERROR(IF(M25>0,ROUNDUP(Premissas!$B$12/M25,0),"sem lucro"),"") -> 117 | S25: Comprar (kit Pele de Vidro) | T25: S | V25: =IF(AND(T25="S",ISNUMBER(L25),ISNUMBER(F25)),L25*F25*X25,0) -> 202.8 | W25: =IF(AND(T25="S",ISNUMBER(Q25)),Q25*X25,0) -> 103.1334 | X25: 12 | Y25: =IF(AND(T25="S",ISNUMBER(G25)),G25*X25,0) -> 75.6
A26: P25 | B26: Sérum Facial Vitamina C Reflection 30ml | C26: Safira | D26: Skincare | E26: 2 | F26: 1 | G26: 6.3 | H26: =IF(ISNUMBER(G26),IFERROR(G26/F26,""),"") -> 6.3 | I26: 15 | J26: 20 | K26: Estimado | L26: 16.9 | M26: =IFERROR(L26*(1-Premissas!$B$5)*(1-Premissas!$B$6)-H26-Premissas!$B$7,"") -> 8.59445 | N26: =IFERROR(M26/L26,"") -> 0.50854734 | O26: =IFERROR(L26*(1-Premissas!$B$8)-Premissas!$B$9-H26-Premissas!$B$7,"") -> 1.322 | P26: =IFERROR(L26*(1-Premissas!$B$10)-Premissas!$B$11-H26-Premissas!$B$7,"") -> 2.22 | Q26: =IFERROR(M26*F26,"") -> 8.59445 | R26: =IFERROR(IF(M26>0,ROUNDUP(Premissas!$B$12/M26,0),"sem lucro"),"") -> 117 | S26: Comprar (kit Pele de Vidro) | T26: S | V26: =IF(AND(T26="S",ISNUMBER(L26),ISNUMBER(F26)),L26*F26*X26,0) -> 202.8 | W26: =IF(AND(T26="S",ISNUMBER(Q26)),Q26*X26,0) -> 103.1334 | X26: 12 | Y26: =IF(AND(T26="S",ISNUMBER(G26)),G26*X26,0) -> 75.6
A27: P26 | B27: Creme Hidratante Ureia 3% 200g | C27: Safira | D27: Corpo | E27: 2 | F27: 1 | G27: 6.9 | H27: =IF(ISNUMBER(G27),IFERROR(G27/F27,""),"") -> 6.9 | I27: 20 | J27: 30 | K27: Estimado | L27: 19.9 | M27: =IFERROR(L27*(1-Premissas!$B$5)*(1-Premissas!$B$6)-H27-Premissas!$B$7,"") -> 10.81595 | N27: =IFERROR(M27/L27,"") -> 0.54351508 | O27: =IFERROR(L27*(1-Premissas!$B$8)-Premissas!$B$9-H27-Premissas!$B$7,"") -> 3.362 | P27: =IFERROR(L27*(1-Premissas!$B$10)-Premissas!$B$11-H27-Premissas!$B$7,"") -> 4.02 | Q27: =IFERROR(M27*F27,"") -> 10.81595 | R27: =IFERROR(IF(M27>0,ROUNDUP(Premissas!$B$12/M27,0),"sem lucro"),"") -> 93 | S27: Comprar | T27: S | U27: Pesado: frete mais caro. Melhor no seu site | V27: =IF(AND(T27="S",ISNUMBER(L27),ISNUMBER(F27)),L27*F27*X27,0) -> 238.8 | W27: =IF(AND(T27="S",ISNUMBER(Q27)),Q27*X27,0) -> 129.7914 | X27: 12 | Y27: =IF(AND(T27="S",ISNUMBER(G27)),G27*X27,0) -> 82.8
A28: P27 | B28: Batom Brilho Natural | C28: Melana | D28: Maquiagem – Lábios | E28: 2 | F28: 24 | G28: 165.3 | H28: =IF(ISNUMBER(G28),IFERROR(G28/F28,""),"") -> 6.8875 | I28: 14.9 | J28: 14.9 | K28: Estimado | L28: 14.9 | M28: =IFERROR(L28*(1-Premissas!$B$5)*(1-Premissas!$B$6)-H28-Premissas!$B$7,"") -> 6.12595 | N28: =IFERROR(M28/L28,"") -> 0.41113758 | O28: =IFERROR(L28*(1-Premissas!$B$8)-Premissas!$B$9-H28-Premissas!$B$7,"") -> -1.0255 | P28: =IFERROR(L28*(1-Premissas!$B$10)-Premissas!$B$11-H28-Premissas!$B$7,"") -> 0.0325 | Q28: =IFERROR(M28*F28,"") -> 147.0228 | R28: =IFERROR(IF(M28>0,ROUNDUP(Premissas!$B$12/M28,0),"sem lucro"),"") -> 164 | S28: Opcional | T28: N | V28: =IF(AND(T28="S",ISNUMBER(L28),ISNUMBER(F28)),L28*F28*X28,0) -> 0 | W28: =IF(AND(T28="S",ISNUMBER(Q28)),Q28*X28,0) -> 0 | X28: 1 | Y28: =IF(AND(T28="S",ISNUMBER(G28)),G28*X28,0) -> 0
A29: P28 | B29: Lip Oil Fruit Juice (LG007) | C29: Hudamoji | D29: Maquiagem – Lábios | E29: 2 | F29: 24 | G29: 95.6 | H29: =IF(ISNUMBER(G29),IFERROR(G29/F29,""),"") -> 3.9833333 | I29: 7.39 | J29: 7.39 | K29: Confirmado | L29: 9.9 | M29: =IFERROR(L29*(1-Premissas!$B$5)*(1-Premissas!$B$6)-H29-Premissas!$B$7,"") -> 4.3276167 | N29: =IFERROR(M29/L29,"") -> 0.437133 | O29: =IFERROR(L29*(1-Premissas!$B$8)-Premissas!$B$9-H29-Premissas!$B$7,"") -> -2.5213333 | P29: =IFERROR(L29*(1-Premissas!$B$10)-Premissas!$B$11-H29-Premissas!$B$7,"") -> -1.0633333 | Q29: =IFERROR(M29*F29,"") -> 103.8628 | R29: =IFERROR(IF(M29>0,ROUNDUP(Premissas!$B$12/M29,0),"sem lucro"),"") -> 232 | S29: Opcional | T29: N | V29: =IF(AND(T29="S",ISNUMBER(L29),ISNUMBER(F29)),L29*F29*X29,0) -> 0 | W29: =IF(AND(T29="S",ISNUMBER(Q29)),Q29*X29,0) -> 0 | X29: 1 | Y29: =IF(AND(T29="S",ISNUMBER(G29)),G29*X29,0) -> 0
A30: P29 | B30: Lip Gloss Alta Pigmentação | C30: Hudamoji | D30: Maquiagem – Lábios | E30: 2 | F30: 24 | G30: 147.5 | H30: =IF(ISNUMBER(G30),IFERROR(G30/F30,""),"") -> 6.1458333 | I30: 12.9 | J30: 12.9 | K30: Estimado | L30: 12.9 | M30: =IFERROR(L30*(1-Premissas!$B$5)*(1-Premissas!$B$6)-H30-Premissas!$B$7,"") -> 4.9866167 | N30: =IFERROR(M30/L30,"") -> 0.38655943 | O30: =IFERROR(L30*(1-Premissas!$B$8)-Premissas!$B$9-H30-Premissas!$B$7,"") -> -2.0438333 | P30: =IFERROR(L30*(1-Premissas!$B$10)-Premissas!$B$11-H30-Premissas!$B$7,"") -> -0.82583333 | Q30: =IFERROR(M30*F30,"") -> 119.6788 | R30: =IFERROR(IF(M30>0,ROUNDUP(Premissas!$B$12/M30,0),"sem lucro"),"") -> 201 | S30: Limitar (muitos gloss) | T30: N | V30: =IF(AND(T30="S",ISNUMBER(L30),ISNUMBER(F30)),L30*F30*X30,0) -> 0 | W30: =IF(AND(T30="S",ISNUMBER(Q30)),Q30*X30,0) -> 0 | X30: 1 | Y30: =IF(AND(T30="S",ISNUMBER(G30)),G30*X30,0) -> 0
A31: P30 | B31: Iluminador Compacto | C31: JummyJu | D31: Maquiagem – Rosto | E31: 2 | F31: 24 | G31: 113.3 | H31: =IF(ISNUMBER(G31),IFERROR(G31/F31,""),"") -> 4.7208333 | I31: 12.9 | J31: 12.9 | K31: Estimado | L31: 12.9 | M31: =IFERROR(L31*(1-Premissas!$B$5)*(1-Premissas!$B$6)-H31-Premissas!$B$7,"") -> 6.4116167 | N31: =IFERROR(M31/L31,"") -> 0.49702455 | O31: =IFERROR(L31*(1-Premissas!$B$8)-Premissas!$B$9-H31-Premissas!$B$7,"") -> -0.61883333 | P31: =IFERROR(L31*(1-Premissas!$B$10)-Premissas!$B$11-H31-Premissas!$B$7,"") -> 0.59916667 | Q31: =IFERROR(M31*F31,"") -> 153.8788 | R31: =IFERROR(IF(M31>0,ROUNDUP(Premissas!$B$12/M31,0),"sem lucro"),"") -> 156 | S31: Opcional | T31: N | V31: =IF(AND(T31="S",ISNUMBER(L31),ISNUMBER(F31)),L31*F31*X31,0) -> 0 | W31: =IF(AND(T31="S",ISNUMBER(Q31)),Q31*X31,0) -> 0 | X31: 1 | Y31: =IF(AND(T31="S",ISNUMBER(G31)),G31*X31,0) -> 0
A32: P31 | B32: Máscara para Sobrancelhas Tatoo Brow | C32: Femme Paris | D32: Maquiagem – Sobrancelhas | E32: 2 | F32: 24 | G32: 110.8 | H32: =IF(ISNUMBER(G32),IFERROR(G32/F32,""),"") -> 4.6166667 | I32: 12 | J32: 15 | K32: Estimado | L32: 12.9 | M32: =IFERROR(L32*(1-Premissas!$B$5)*(1-Premissas!$B$6)-H32-Premissas!$B$7,"") -> 6.5157833 | N32: =IFERROR(M32/L32,"") -> 0.50509948 | O32: =IFERROR(L32*(1-Premissas!$B$8)-Premissas!$B$9-H32-Premissas!$B$7,"") -> -0.51466667 | P32: =IFERROR(L32*(1-Premissas!$B$10)-Premissas!$B$11-H32-Premissas!$B$7,"") -> 0.70333333 | Q32: =IFERROR(M32*F32,"") -> 156.3788 | R32: =IFERROR(IF(M32>0,ROUNDUP(Premissas!$B$12/M32,0),"sem lucro"),"") -> 154 | S32: Comprar (kits) | T32: S | V32: =IF(AND(T32="S",ISNUMBER(L32),ISNUMBER(F32)),L32*F32*X32,0) -> 309.6 | W32: =IF(AND(T32="S",ISNUMBER(Q32)),Q32*X32,0) -> 156.3788 | X32: 1 | Y32: =IF(AND(T32="S",ISNUMBER(G32)),G32*X32,0) -> 110.8
A33: P32 | B33: Contorno Stick | C33: Femme Paris | D33: Maquiagem – Rosto | E33: 2 | F33: 24 | G33: 151.7 | H33: =IF(ISNUMBER(G33),IFERROR(G33/F33,""),"") -> 6.3208333 | I33: 15.9 | J33: 15.9 | K33: Estimado | L33: 15.9 | M33: =IFERROR(L33*(1-Premissas!$B$5)*(1-Premissas!$B$6)-H33-Premissas!$B$7,"") -> 7.6331167 | N33: =IFERROR(M33/L33,"") -> 0.48007023 | O33: =IFERROR(L33*(1-Premissas!$B$8)-Premissas!$B$9-H33-Premissas!$B$7,"") -> 0.42116667 | P33: =IFERROR(L33*(1-Premissas!$B$10)-Premissas!$B$11-H33-Premissas!$B$7,"") -> 1.3991667 | Q33: =IFERROR(M33*F33,"") -> 183.1948 | R33: =IFERROR(IF(M33>0,ROUNDUP(Premissas!$B$12/M33,0),"sem lucro"),"") -> 132 | S33: Comprar | T33: S | V33: =IF(AND(T33="S",ISNUMBER(L33),ISNUMBER(F33)),L33*F33*X33,0) -> 381.6 | W33: =IF(AND(T33="S",ISNUMBER(Q33)),Q33*X33,0) -> 183.1948 | X33: 1 | Y33: =IF(AND(T33="S",ISNUMBER(G33)),G33*X33,0) -> 151.7
A34: P33 | B34: Lip Gloss Peel-Off | C34: Femme Paris | D34: Maquiagem – Lábios | E34: 3 | F34: 24 | G34: 131.3 | H34: =IF(ISNUMBER(G34),IFERROR(G34/F34,""),"") -> 5.4708333 | I34: 12.9 | J34: 12.9 | K34: Estimado | L34: 12.9 | M34: =IFERROR(L34*(1-Premissas!$B$5)*(1-Premissas!$B$6)-H34-Premissas!$B$7,"") -> 5.6616167 | N34: =IFERROR(M34/L34,"") -> 0.43888501 | O34: =IFERROR(L34*(1-Premissas!$B$8)-Premissas!$B$9-H34-Premissas!$B$7,"") -> -1.3688333 | P34: =IFERROR(L34*(1-Premissas!$B$10)-Premissas!$B$11-H34-Premissas!$B$7,"") -> -0.15083333 | Q34: =IFERROR(M34*F34,"") -> 135.8788 | R34: =IFERROR(IF(M34>0,ROUNDUP(Premissas!$B$12/M34,0),"sem lucro"),"") -> 177 | S34: Comprar (1 das 2 linhas de gloss) | T34: S | U34: Tendência | V34: =IF(AND(T34="S",ISNUMBER(L34),ISNUMBER(F34)),L34*F34*X34,0) -> 309.6 | W34: =IF(AND(T34="S",ISNUMBER(Q34)),Q34*X34,0) -> 135.8788 | X34: 1 | Y34: =IF(AND(T34="S",ISNUMBER(G34)),G34*X34,0) -> 131.3
A35: P34 | B35: Conjunto de Pentes e Acessórios c/9 peças | C35: — | D35: Cabelos | E35: 3 | F35: 1 | G35: 6.5 | H35: =IF(ISNUMBER(G35),IFERROR(G35/F35,""),"") -> 6.5 | I35: 15 | J35: 20 | K35: Estimado | L35: 16.9 | M35: =IFERROR(L35*(1-Premissas!$B$5)*(1-Premissas!$B$6)-H35-Premissas!$B$7,"") -> 8.39445 | N35: =IFERROR(M35/L35,"") -> 0.49671302 | O35: =IFERROR(L35*(1-Premissas!$B$8)-Premissas!$B$9-H35-Premissas!$B$7,"") -> 1.122 | P35: =IFERROR(L35*(1-Premissas!$B$10)-Premissas!$B$11-H35-Premissas!$B$7,"") -> 2.02 | Q35: =IFERROR(M35*F35,"") -> 8.39445 | R35: =IFERROR(IF(M35>0,ROUNDUP(Premissas!$B$12/M35,0),"sem lucro"),"") -> 120 | S35: Comprar | T35: S | V35: =IF(AND(T35="S",ISNUMBER(L35),ISNUMBER(F35)),L35*F35*X35,0) -> 202.8 | W35: =IF(AND(T35="S",ISNUMBER(Q35)),Q35*X35,0) -> 100.7334 | X35: 12 | Y35: =IF(AND(T35="S",ISNUMBER(G35)),G35*X35,0) -> 78
A36: P35 | B36: Mini Esponja para Maquiagem c/4 | C36: Rub… (confirmar marca) | D36: Acessórios | E36: 3 | F36: 1 | G36: 3.2 | H36: =IF(ISNUMBER(G36),IFERROR(G36/F36,""),"") -> 3.2 | I36: 9.9 | J36: 9.9 | K36: Estimado | L36: 9.9 | M36: =IFERROR(L36*(1-Premissas!$B$5)*(1-Premissas!$B$6)-H36-Premissas!$B$7,"") -> 5.11095 | N36: =IFERROR(M36/L36,"") -> 0.51625758 | O36: =IFERROR(L36*(1-Premissas!$B$8)-Premissas!$B$9-H36-Premissas!$B$7,"") -> -1.738 | P36: =IFERROR(L36*(1-Premissas!$B$10)-Premissas!$B$11-H36-Premissas!$B$7,"") -> -0.28 | Q36: =IFERROR(M36*F36,"") -> 5.11095 | R36: =IFERROR(IF(M36>0,ROUNDUP(Premissas!$B$12/M36,0),"sem lucro"),"") -> 196 | S36: Opcional | T36: N | V36: =IF(AND(T36="S",ISNUMBER(L36),ISNUMBER(F36)),L36*F36*X36,0) -> 0 | W36: =IF(AND(T36="S",ISNUMBER(Q36)),Q36*X36,0) -> 0 | X36: 12 | Y36: =IF(AND(T36="S",ISNUMBER(G36)),G36*X36,0) -> 0
A37: P36 | B37: Pó de Tapioca Lilás Selva Neon | C37: Miss Rôse | D37: Maquiagem – Rosto | E37: 3 | F37: 15 | G37: 49.5 | H37: =IF(ISNUMBER(G37),IFERROR(G37/F37,""),"") -> 3.3 | I37: 7.54 | J37: 11.99 | K37: Confirmado | L37: 11.9 | M37: =IFERROR(L37*(1-Premissas!$B$5)*(1-Premissas!$B$6)-H37-Premissas!$B$7,"") -> 6.89195 | N37: =IFERROR(M37/L37,"") -> 0.57915546 | O37: =IFERROR(L37*(1-Premissas!$B$8)-Premissas!$B$9-H37-Premissas!$B$7,"") -> -0.078 | P37: =IFERROR(L37*(1-Premissas!$B$10)-Premissas!$B$11-H37-Premissas!$B$7,"") -> 1.22 | Q37: =IFERROR(M37*F37,"") -> 103.37925 | R37: =IFERROR(IF(M37>0,ROUNDUP(Premissas!$B$12/M37,0),"sem lucro"),"") -> 146 | S37: Comprar | T37: S | U37: Melhor custo da lista | V37: =IF(AND(T37="S",ISNUMBER(L37),ISNUMBER(F37)),L37*F37*X37,0) -> 178.5 | W37: =IF(AND(T37="S",ISNUMBER(Q37)),Q37*X37,0) -> 103.37925 | X37: 1 | Y37: =IF(AND(T37="S",ISNUMBER(G37)),G37*X37,0) -> 49.5
A38: P37 | B38: Tint Brow Preenche Sobrancelha | C38: Wike Make | D38: Maquiagem – Sobrancelhas | E38: 3 | F38: 24 | G38: 150.6 | H38: =IF(ISNUMBER(G38),IFERROR(G38/F38,""),"") -> 6.275 | I38: 12.9 | J38: 12.9 | K38: Estimado | L38: 12.9 | M38: =IFERROR(L38*(1-Premissas!$B$5)*(1-Premissas!$B$6)-H38-Premissas!$B$7,"") -> 4.85745 | N38: =IFERROR(M38/L38,"") -> 0.37654651 | O38: =IFERROR(L38*(1-Premissas!$B$8)-Premissas!$B$9-H38-Premissas!$B$7,"") -> -2.173 | P38: =IFERROR(L38*(1-Premissas!$B$10)-Premissas!$B$11-H38-Premissas!$B$7,"") -> -0.955 | Q38: =IFERROR(M38*F38,"") -> 116.5788 | R38: =IFERROR(IF(M38>0,ROUNDUP(Premissas!$B$12/M38,0),"sem lucro"),"") -> 206 | S38: Comprar (kit Sobrancelha) | T38: S | V38: =IF(AND(T38="S",ISNUMBER(L38),ISNUMBER(F38)),L38*F38*X38,0) -> 309.6 | W38: =IF(AND(T38="S",ISNUMBER(Q38)),Q38*X38,0) -> 116.5788 | X38: 1 | Y38: =IF(AND(T38="S",ISNUMBER(G38)),G38*X38,0) -> 150.6
A39: P38 | B39: Gel Fixador de Sobrancelhas com Pente | C39: Wike Make | D39: Maquiagem – Sobrancelhas | E39: 3 | F39: 24 | G39: 138.2 | H39: =IF(ISNUMBER(G39),IFERROR(G39/F39,""),"") -> 5.7583333 | I39: 12.9 | J39: 12.9 | K39: Estimado | L39: 12.9 | M39: =IFERROR(L39*(1-Premissas!$B$5)*(1-Premissas!$B$6)-H39-Premissas!$B$7,"") -> 5.3741167 | N39: =IFERROR(M39/L39,"") -> 0.41659819 | O39: =IFERROR(L39*(1-Premissas!$B$8)-Premissas!$B$9-H39-Premissas!$B$7,"") -> -1.6563333 | P39: =IFERROR(L39*(1-Premissas!$B$10)-Premissas!$B$11-H39-Premissas!$B$7,"") -> -0.43833333 | Q39: =IFERROR(M39*F39,"") -> 128.9788 | R39: =IFERROR(IF(M39>0,ROUNDUP(Premissas!$B$12/M39,0),"sem lucro"),"") -> 187 | S39: Comprar (kit Sobrancelha) | T39: S | V39: =IF(AND(T39="S",ISNUMBER(L39),ISNUMBER(F39)),L39*F39*X39,0) -> 309.6 | W39: =IF(AND(T39="S",ISNUMBER(Q39)),Q39*X39,0) -> 128.9788 | X39: 1 | Y39: =IF(AND(T39="S",ISNUMBER(G39)),G39*X39,0) -> 138.2
A40: P39 | B40: Lip Gloss Candy | C40: Wike Make | D40: Maquiagem – Lábios | E40: 3 | F40: 24 | G40: 153.6 | H40: =IF(ISNUMBER(G40),IFERROR(G40/F40,""),"") -> 6.4 | I40: 7.52 | J40: 10 | K40: Confirmado | L40: 11.9 | M40: =IFERROR(L40*(1-Premissas!$B$5)*(1-Premissas!$B$6)-H40-Premissas!$B$7,"") -> 3.79195 | N40: =IFERROR(M40/L40,"") -> 0.31865126 | O40: =IFERROR(L40*(1-Premissas!$B$8)-Premissas!$B$9-H40-Premissas!$B$7,"") -> -3.178 | P40: =IFERROR(L40*(1-Premissas!$B$10)-Premissas!$B$11-H40-Premissas!$B$7,"") -> -1.88 | Q40: =IFERROR(M40*F40,"") -> 91.0068 | R40: =IFERROR(IF(M40>0,ROUNDUP(Premissas!$B$12/M40,0),"sem lucro"),"") -> 264 | S40: Evitar (margem baixa) | T40: N | U40: Vendido por R$ 7,50–10 em outras lojas | V40: =IF(AND(T40="S",ISNUMBER(L40),ISNUMBER(F40)),L40*F40*X40,0) -> 0 | W40: =IF(AND(T40="S",ISNUMBER(Q40)),Q40*X40,0) -> 0 | X40: 1 | Y40: =IF(AND(T40="S",ISNUMBER(G40)),G40*X40,0) -> 0
...

Sheet Kits
A1: Kit | B1: Item 1 | C1: Item 2 | D1: Item 3 | E1: Item 4 | F1: Item 5 | G1: Custo do kit | H1: Preço de venda | I1: Lucro seu site | J1: Lucro Mercado Livre | K1: Lucro Shopee | L1: Kits/mês p/ meta (seu site)
A2: Pele de Vidro | B2: P23 | C2: P25 | D2: P24 | G2: =IFERROR(INDEX(Produtos!$H$2:$H$110,MATCH(B2,Produtos!$A$2:$A$110,0)),0)+IFERROR(INDEX(Produtos!$H$2:$H$110,MATCH(C2,Produtos!$A$2:$A$110,0)),0)+IFERROR(INDEX(Produtos!$H$2:$H$110,MATCH(D2,Produtos!$A$2:$A$110,0)),0)+IFERROR(INDEX(Produtos!$H$2:$H$110,MATCH(E2,Produtos!$A$2:$A$110,0)),0)+IFERROR(INDEX(Produtos!$H$2:$H$110,MATCH(F2,Produtos!$A$2:$A$110,0)),0) -> 18.9 | H2: 49.9 | I2: =H2*(1-Premissas!$B$5)*(1-Premissas!$B$6)-G2-Premissas!$B$7 -> 27.03095 | J2: =H2*(1-Premissas!$B$8)-Premissas!$B$9-G2-Premissas!$B$7 -> 17.762 | K2: =H2*(1-Premissas!$B$10)-Premissas!$B$11-G2-Premissas!$B$7 -> 16.02 | L2: =IF(I2>0,ROUNDUP(Premissas!$B$12/I2,0),"sem lucro") -> 37
A3: Pele Perfeita | B3: P02 | C3: P06 | D3: P07 | E3: P36 | G3: =IFERROR(INDEX(Produtos!$H$2:$H$110,MATCH(B3,Produtos!$A$2:$A$110,0)),0)+IFERROR(INDEX(Produtos!$H$2:$H$110,MATCH(C3,Produtos!$A$2:$A$110,0)),0)+IFERROR(INDEX(Produtos!$H$2:$H$110,MATCH(D3,Produtos!$A$2:$A$110,0)),0)+IFERROR(INDEX(Produtos!$H$2:$H$110,MATCH(E3,Produtos!$A$2:$A$110,0)),0)+IFERROR(INDEX(Produtos!$H$2:$H$110,MATCH(F3,Produtos!$A$2:$A$110,0)),0) -> 23.595833 | H3: 49.9 | I3: =H3*(1-Premissas!$B$5)*(1-Premissas!$B$6)-G3-Premissas!$B$7 -> 22.335117 | J3: =H3*(1-Premissas!$B$8)-Premissas!$B$9-G3-Premissas!$B$7 -> 13.066167 | K3: =H3*(1-Premissas!$B$10)-Premissas!$B$11-G3-Premissas!$B$7 -> 11.324167 | L3: =IF(I3>0,ROUNDUP(Premissas!$B$12/I3,0),"sem lucro") -> 45
A4: Rotina Skincare | B4: P09 | C4: P10 | D4: P12 | G4: =IFERROR(INDEX(Produtos!$H$2:$H$110,MATCH(B4,Produtos!$A$2:$A$110,0)),0)+IFERROR(INDEX(Produtos!$H$2:$H$110,MATCH(C4,Produtos!$A$2:$A$110,0)),0)+IFERROR(INDEX(Produtos!$H$2:$H$110,MATCH(D4,Produtos!$A$2:$A$110,0)),0)+IFERROR(INDEX(Produtos!$H$2:$H$110,MATCH(E4,Produtos!$A$2:$A$110,0)),0)+IFERROR(INDEX(Produtos!$H$2:$H$110,MATCH(F4,Produtos!$A$2:$A$110,0)),0) -> 17.1 | H4: 39.9 | I4: =H4*(1-Premissas!$B$5)*(1-Premissas!$B$6)-G4-Premissas!$B$7 -> 19.42595 | J4: =H4*(1-Premissas!$B$8)-Premissas!$B$9-G4-Premissas!$B$7 -> 10.762 | K4: =H4*(1-Premissas!$B$10)-Premissas!$B$11-G4-Premissas!$B$7 -> 9.82 | L4: =IF(I4>0,ROUNDUP(Premissas!$B$12/I4,0),"sem lucro") -> 52
A5: Olhar Poderoso | B5: P22 | C5: P22 | D5: P22 | E5: P105 | F5: P31 | G5: =IFERROR(INDEX(Produtos!$H$2:$H$110,MATCH(B5,Produtos!$A$2:$A$110,0)),0)+IFERROR(INDEX(Produtos!$H$2:$H$110,MATCH(C5,Produtos!$A$2:$A$110,0)),0)+IFERROR(INDEX(Produtos!$H$2:$H$110,MATCH(D5,Produtos!$A$2:$A$110,0)),0)+IFERROR(INDEX(Produtos!$H$2:$H$110,MATCH(E5,Produtos!$A$2:$A$110,0)),0)+IFERROR(INDEX(Produtos!$H$2:$H$110,MATCH(F5,Produtos!$A$2:$A$110,0)),0) -> 21.110833 | H5: 44.9 | I5: =H5*(1-Premissas!$B$5)*(1-Premissas!$B$6)-G5-Premissas!$B$7 -> 20.117617 | J5: =H5*(1-Premissas!$B$8)-Premissas!$B$9-G5-Premissas!$B$7 -> 11.151167 | K5: =H5*(1-Premissas!$B$10)-Premissas!$B$11-G5-Premissas!$B$7 -> 9.8091667 | L5: =IF(I5>0,ROUNDUP(Premissas!$B$12/I5,0),"sem lucro") -> 50
A6: Sobrancelha Perfeita | B6: P37 | C6: P38 | D6: P31 | G6: =IFERROR(INDEX(Produtos!$H$2:$H$110,MATCH(B6,Produtos!$A$2:$A$110,0)),0)+IFERROR(INDEX(Produtos!$H$2:$H$110,MATCH(C6,Produtos!$A$2:$A$110,0)),0)+IFERROR(INDEX(Produtos!$H$2:$H$110,MATCH(D6,Produtos!$A$2:$A$110,0)),0)+IFERROR(INDEX(Produtos!$H$2:$H$110,MATCH(E6,Produtos!$A$2:$A$110,0)),0)+IFERROR(INDEX(Produtos!$H$2:$H$110,MATCH(F6,Produtos!$A$2:$A$110,0)),0) -> 16.65 | H6: 34.9 | I6: =H6*(1-Premissas!$B$5)*(1-Premissas!$B$6)-G6-Premissas!$B$7 -> 15.17345 | J6: =H6*(1-Premissas!$B$8)-Premissas!$B$9-G6-Premissas!$B$7 -> 6.812 | K6: =H6*(1-Premissas!$B$10)-Premissas!$B$11-G6-Premissas!$B$7 -> 6.27 | L6: =IF(I6>0,ROUNDUP(Premissas!$B$12/I6,0),"sem lucro") -> 66
A7: Lábios Suculentos | B7: P28 | C7: P29 | D7: P27 | G7: =IFERROR(INDEX(Produtos!$H$2:$H$110,MATCH(B7,Produtos!$A$2:$A$110,0)),0)+IFERROR(INDEX(Produtos!$H$2:$H$110,MATCH(C7,Produtos!$A$2:$A$110,0)),0)+IFERROR(INDEX(Produtos!$H$2:$H$110,MATCH(D7,Produtos!$A$2:$A$110,0)),0)+IFERROR(INDEX(Produtos!$H$2:$H$110,MATCH(E7,Produtos!$A$2:$A$110,0)),0)+IFERROR(INDEX(Produtos!$H$2:$H$110,MATCH(F7,Produtos!$A$2:$A$110,0)),0) -> 17.016667 | H7: 34.9 | I7: =H7*(1-Premissas!$B$5)*(1-Premissas!$B$6)-G7-Premissas!$B$7 -> 14.806783 | J7: =H7*(1-Premissas!$B$8)-Premissas!$B$9-G7-Premissas!$B$7 -> 6.4453333 | K7: =H7*(1-Premissas!$B$10)-Premissas!$B$11-G7-Premissas!$B$7 -> 5.9033333 | L7: =IF(I7>0,ROUNDUP(Premissas!$B$12/I7,0),"sem lucro") -> 68
A8: Perfumada (splash + creme) | B8: P52 | C8: P54 | G8: =IFERROR(INDEX(Produtos!$H$2:$H$110,MATCH(B8,Produtos!$A$2:$A$110,0)),0)+IFERROR(INDEX(Produtos!$H$2:$H$110,MATCH(C8,Produtos!$A$2:$A$110,0)),0)+IFERROR(INDEX(Produtos!$H$2:$H$110,MATCH(D8,Produtos!$A$2:$A$110,0)),0)+IFERROR(INDEX(Produtos!$H$2:$H$110,MATCH(E8,Produtos!$A$2:$A$110,0)),0)+IFERROR(INDEX(Produtos!$H$2:$H$110,MATCH(F8,Produtos!$A$2:$A$110,0)),0) -> 13.4 | H8: 44.9 | I8: =H8*(1-Premissas!$B$5)*(1-Premissas!$B$6)-G8-Premissas!$B$7 -> 27.82845 | J8: =H8*(1-Premissas!$B$8)-Premissas!$B$9-G8-Premissas!$B$7 -> 18.862 | K8: =H8*(1-Premissas!$B$10)-Premissas!$B$11-G8-Premissas!$B$7 -> 17.52 | L8: =IF(I8>0,ROUNDUP(Premissas!$B$12/I8,0),"sem lucro") -> 36
A9: Presente Masculino (2 splash) | B9: P53 | C9: P53 | G9: =IFERROR(INDEX(Produtos!$H$2:$H$110,MATCH(B9,Produtos!$A$2:$A$110,0)),0)+IFERROR(INDEX(Produtos!$H$2:$H$110,MATCH(C9,Produtos!$A$2:$A$110,0)),0)+IFERROR(INDEX(Produtos!$H$2:$H$110,MATCH(D9,Produtos!$A$2:$A$110,0)),0)+IFERROR(INDEX(Produtos!$H$2:$H$110,MATCH(E9,Produtos!$A$2:$A$110,0)),0)+IFERROR(INDEX(Produtos!$H$2:$H$110,MATCH(F9,Produtos!$A$2:$A$110,0)),0) -> 13.6 | H9: 44.9 | I9: =H9*(1-Premissas!$B$5)*(1-Premissas!$B$6)-G9-Premissas!$B$7 -> 27.62845 | J9: =H9*(1-Premissas!$B$8)-Premissas!$B$9-G9-Premissas!$B$7 -> 18.662 | K9: =H9*(1-Premissas!$B$10)-Premissas!$B$11-G9-Premissas!$B$7 -> 17.32 | L9: =IF(I9>0,ROUNDUP(Premissas!$B$12/I9,0),"sem lucro") -> 37
A10: Make Completa | B10: P72 | C10: P69 | D10: P66 | E10: P58 | G10: =IFERROR(INDEX(Produtos!$H$2:$H$110,MATCH(B10,Produtos!$A$2:$A$110,0)),0)+IFERROR(INDEX(Produtos!$H$2:$H$110,MATCH(C10,Produtos!$A$2:$A$110,0)),0)+IFERROR(INDEX(Produtos!$H$2:$H$110,MATCH(D10,Produtos!$A$2:$A$110,0)),0)+IFERROR(INDEX(Produtos!$H$2:$H$110,MATCH(E10,Produtos!$A$2:$A$110,0)),0)+IFERROR(INDEX(Produtos!$H$2:$H$110,MATCH(F10,Produtos!$A$2:$A$110,0)),0) -> 22.533125 | H10: 59.9 | I10: =H10*(1-Premissas!$B$5)*(1-Premissas!$B$6)-G10-Premissas!$B$7 -> 32.802825 | J10: =H10*(1-Premissas!$B$8)-Premissas!$B$9-G10-Premissas!$B$7 -> 22.928875 | K10: =H10*(1-Premissas!$B$10)-Premissas!$B$11-G10-Premissas!$B$7 -> 20.386875 | L10: =IF(I10>0,ROUNDUP(Premissas!$B$12/I10,0),"sem lucro") -> 31
A11: Pele Pink 21 | B11: P89 | C11: P66 | D11: P92 | E11: P58 | G11: =IFERROR(INDEX(Produtos!$H$2:$H$110,MATCH(B11,Produtos!$A$2:$A$110,0)),0)+IFERROR(INDEX(Produtos!$H$2:$H$110,MATCH(C11,Produtos!$A$2:$A$110,0)),0)+IFERROR(INDEX(Produtos!$H$2:$H$110,MATCH(D11,Produtos!$A$2:$A$110,0)),0)+IFERROR(INDEX(Produtos!$H$2:$H$110,MATCH(E11,Produtos!$A$2:$A$110,0)),0)+IFERROR(INDEX(Produtos!$H$2:$H$110,MATCH(F11,Produtos!$A$2:$A$110,0)),0) -> 15.463958 | H11: 49.9 | I11: =H11*(1-Premissas!$B$5)*(1-Premissas!$B$6)-G11-Premissas!$B$7 -> 30.466992 | J11: =H11*(1-Premissas!$B$8)-Premissas!$B$9-G11-Premissas!$B$7 -> 21.198042 | K11: =H11*(1-Premissas!$B$10)-Premissas!$B$11-G11-Premissas!$B$7 -> 19.456042 | L11: =IF(I11>0,ROUNDUP(Premissas!$B$12/I11,0),"sem lucro") -> 33
A13: Os itens são IDs da aba Produtos (passe o mouse para ver o nome). Repetir um ID = mais de uma unidade no kit.
